[2025-02-17T18:38:24.652+0000] {taskinstance.py:1083} INFO - Dependencies all met for <TaskInstance: etl_pipeline.transform manual__2025-02-17T18:38:22.524720+00:00 [queued]>
[2025-02-17T18:38:24.670+0000] {taskinstance.py:1083} INFO - Dependencies all met for <TaskInstance: etl_pipeline.transform manual__2025-02-17T18:38:22.524720+00:00 [queued]>
[2025-02-17T18:38:24.671+0000] {taskinstance.py:1279} INFO - 
--------------------------------------------------------------------------------
[2025-02-17T18:38:24.673+0000] {taskinstance.py:1280} INFO - Starting attempt 1 of 2
[2025-02-17T18:38:24.673+0000] {taskinstance.py:1281} INFO - 
--------------------------------------------------------------------------------
[2025-02-17T18:38:24.696+0000] {taskinstance.py:1300} INFO - Executing <Task(PythonOperator): transform> on 2025-02-17 18:38:22.524720+00:00
[2025-02-17T18:38:24.701+0000] {standard_task_runner.py:55} INFO - Started process 375 to run task
[2025-02-17T18:38:24.705+0000] {standard_task_runner.py:82} INFO - Running: ['***', 'tasks', 'run', 'etl_pipeline', 'transform', 'manual__2025-02-17T18:38:22.524720+00:00', '--job-id', '3', '--raw', '--subdir', 'DAGS_FOLDER/etl_dag.py', '--cfg-path', '/tmp/tmp4eb51s1l']
[2025-02-17T18:38:24.707+0000] {standard_task_runner.py:83} INFO - Job 3: Subtask transform
[2025-02-17T18:38:24.723+0000] {logging_mixin.py:137} WARNING - /home/***/.local/lib/python3.7/site-packages/***/settings.py:249 DeprecationWarning: The sql_alchemy_conn option in [core] has been moved to the sql_alchemy_conn option in [database] - the old setting has been used, but please update your config.
[2025-02-17T18:38:24.782+0000] {task_command.py:388} INFO - Running <TaskInstance: etl_pipeline.transform manual__2025-02-17T18:38:22.524720+00:00 [running]> on host ffeed52c0e5e
[2025-02-17T18:38:24.871+0000] {taskinstance.py:1509} INFO - Exporting the following env vars:
AIRFLOW_CTX_DAG_OWNER=***
AIRFLOW_CTX_DAG_ID=etl_pipeline
AIRFLOW_CTX_TASK_ID=transform
AIRFLOW_CTX_EXECUTION_DATE=2025-02-17T18:38:22.524720+00:00
AIRFLOW_CTX_TRY_NUMBER=1
AIRFLOW_CTX_DAG_RUN_ID=manual__2025-02-17T18:38:22.524720+00:00
[2025-02-17T18:38:24.881+0000] {taskinstance.py:1768} ERROR - Task failed with exception
Traceback (most recent call last):
  File "/home/airflow/.local/lib/python3.7/site-packages/airflow/operators/python.py", line 175, in execute
    return_value = self.execute_callable()
  File "/home/airflow/.local/lib/python3.7/site-packages/airflow/operators/python.py", line 192, in execute_callable
    return self.python_callable(*self.op_args, **self.op_kwargs)
  File "/opt/airflow/dags/etl_dag.py", line 8, in spark_etl
    subprocess.run(["spark-submit", "/scripts/spark_etl.py"])
  File "/usr/local/lib/python3.7/subprocess.py", line 488, in run
    with Popen(*popenargs, **kwargs) as process:
  File "/usr/local/lib/python3.7/subprocess.py", line 800, in __init__
    restore_signals, start_new_session)
  File "/usr/local/lib/python3.7/subprocess.py", line 1551, in _execute_child
    raise child_exception_type(errno_num, err_msg, err_filename)
PermissionError: [Errno 13] Permission denied: 'spark-submit'
[2025-02-17T18:38:24.907+0000] {taskinstance.py:1323} INFO - Marking task as UP_FOR_RETRY. dag_id=etl_pipeline, task_id=transform, execution_date=20250217T183822, start_date=20250217T183824, end_date=20250217T183824
[2025-02-17T18:38:24.932+0000] {standard_task_runner.py:105} ERROR - Failed to execute job 3 for task transform ([Errno 13] Permission denied: 'spark-submit'; 375)
[2025-02-17T18:38:24.958+0000] {local_task_job.py:208} INFO - Task exited with return code 1
[2025-02-17T18:38:25.014+0000] {taskinstance.py:2578} INFO - 0 downstream tasks scheduled from follow-on schedule check
