[2025-02-18T19:09:40.516+0000] {taskinstance.py:1125} INFO - Dependencies all met for dep_context=non-requeueable deps ti=<TaskInstance: etl_pipeline.transform manual__2025-02-18T19:04:33.581267+00:00 [queued]>
[2025-02-18T19:09:40.531+0000] {taskinstance.py:1125} INFO - Dependencies all met for dep_context=requeueable deps ti=<TaskInstance: etl_pipeline.transform manual__2025-02-18T19:04:33.581267+00:00 [queued]>
[2025-02-18T19:09:40.531+0000] {taskinstance.py:1331} INFO - Starting attempt 2 of 2
[2025-02-18T19:09:40.552+0000] {taskinstance.py:1350} INFO - Executing <Task(PythonOperator): transform> on 2025-02-18 19:04:33.581267+00:00
[2025-02-18T19:09:40.557+0000] {standard_task_runner.py:57} INFO - Started process 254 to run task
[2025-02-18T19:09:40.560+0000] {standard_task_runner.py:84} INFO - Running: ['***', 'tasks', 'run', 'etl_pipeline', 'transform', 'manual__2025-02-18T19:04:33.581267+00:00', '--job-id', '41', '--raw', '--subdir', 'DAGS_FOLDER/etl_dag.py', '--cfg-path', '/tmp/tmpayfn9btw']
[2025-02-18T19:09:40.562+0000] {standard_task_runner.py:85} INFO - Job 41: Subtask transform
[2025-02-18T19:09:40.580+0000] {logging_mixin.py:149} WARNING - /home/***/.local/lib/python3.7/site-packages/***/settings.py:188 DeprecationWarning: The sql_alchemy_conn option in [core] has been moved to the sql_alchemy_conn option in [database] - the old setting has been used, but please update your config.
[2025-02-18T19:09:40.634+0000] {task_command.py:410} INFO - Running <TaskInstance: etl_pipeline.transform manual__2025-02-18T19:04:33.581267+00:00 [running]> on host ff42797578c0
[2025-02-18T19:09:40.758+0000] {taskinstance.py:1570} INFO - Exporting env vars: AIRFLOW_CTX_DAG_OWNER='***' AIRFLOW_CTX_DAG_ID='etl_pipeline' AIRFLOW_CTX_TASK_ID='transform' AIRFLOW_CTX_EXECUTION_DATE='2025-02-18T19:04:33.581267+00:00' AIRFLOW_CTX_TRY_NUMBER='2' AIRFLOW_CTX_DAG_RUN_ID='manual__2025-02-18T19:04:33.581267+00:00'
[2025-02-18T19:09:40.760+0000] {logging_mixin.py:149} INFO - üîç Ejecutando el comando: docker exec etl-pipeline-spark-1 /opt/spark/bin/spark-submit /scripts/spark_etl.py
[2025-02-18T19:09:40.855+0000] {logging_mixin.py:149} INFO - ‚ùå ERROR en Spark ETL:
[2025-02-18T19:09:40.857+0000] {taskinstance.py:1847} ERROR - Task failed with exception
Traceback (most recent call last):
  File "/home/airflow/.local/lib/python3.7/site-packages/airflow/operators/python.py", line 181, in execute
    return_value = self.execute_callable()
  File "/home/airflow/.local/lib/python3.7/site-packages/airflow/operators/python.py", line 198, in execute_callable
    return self.python_callable(*self.op_args, **self.op_kwargs)
  File "/opt/airflow/dags/etl_dag.py", line 22, in spark_etl
    shell=True  # Especificamos shell=True porque estamos ejecutando un comando de bash
  File "/usr/local/lib/python3.7/subprocess.py", line 512, in run
    output=stdout, stderr=stderr)
subprocess.CalledProcessError: Command 'docker exec etl-pipeline-spark-1 /opt/spark/bin/spark-submit /scripts/spark_etl.py' returned non-zero exit status 126.
[2025-02-18T19:09:40.873+0000] {taskinstance.py:1373} INFO - Marking task as FAILED. dag_id=etl_pipeline, task_id=transform, execution_date=20250218T190433, start_date=20250218T190940, end_date=20250218T190940
[2025-02-18T19:09:40.892+0000] {standard_task_runner.py:109} ERROR - Failed to execute job 41 for task transform (Command 'docker exec etl-pipeline-spark-1 /opt/spark/bin/spark-submit /scripts/spark_etl.py' returned non-zero exit status 126.; 254)
[2025-02-18T19:09:40.934+0000] {local_task_job_runner.py:232} INFO - Task exited with return code 1
[2025-02-18T19:09:40.987+0000] {taskinstance.py:2674} INFO - 0 downstream tasks scheduled from follow-on schedule check
