[2025-02-18T19:04:39.006+0000] {taskinstance.py:1125} INFO - Dependencies all met for dep_context=non-requeueable deps ti=<TaskInstance: etl_pipeline.transform manual__2025-02-18T19:04:33.581267+00:00 [queued]>
[2025-02-18T19:04:39.019+0000] {taskinstance.py:1125} INFO - Dependencies all met for dep_context=requeueable deps ti=<TaskInstance: etl_pipeline.transform manual__2025-02-18T19:04:33.581267+00:00 [queued]>
[2025-02-18T19:04:39.020+0000] {taskinstance.py:1331} INFO - Starting attempt 1 of 2
[2025-02-18T19:04:39.041+0000] {taskinstance.py:1350} INFO - Executing <Task(PythonOperator): transform> on 2025-02-18 19:04:33.581267+00:00
[2025-02-18T19:04:39.046+0000] {standard_task_runner.py:57} INFO - Started process 205 to run task
[2025-02-18T19:04:39.052+0000] {standard_task_runner.py:84} INFO - Running: ['***', 'tasks', 'run', 'etl_pipeline', 'transform', 'manual__2025-02-18T19:04:33.581267+00:00', '--job-id', '40', '--raw', '--subdir', 'DAGS_FOLDER/etl_dag.py', '--cfg-path', '/tmp/tmp0qobw3zy']
[2025-02-18T19:04:39.055+0000] {standard_task_runner.py:85} INFO - Job 40: Subtask transform
[2025-02-18T19:04:39.084+0000] {logging_mixin.py:149} WARNING - /home/***/.local/lib/python3.7/site-packages/***/settings.py:188 DeprecationWarning: The sql_alchemy_conn option in [core] has been moved to the sql_alchemy_conn option in [database] - the old setting has been used, but please update your config.
[2025-02-18T19:04:39.150+0000] {task_command.py:410} INFO - Running <TaskInstance: etl_pipeline.transform manual__2025-02-18T19:04:33.581267+00:00 [running]> on host ff42797578c0
[2025-02-18T19:04:39.311+0000] {taskinstance.py:1570} INFO - Exporting env vars: AIRFLOW_CTX_DAG_OWNER='***' AIRFLOW_CTX_DAG_ID='etl_pipeline' AIRFLOW_CTX_TASK_ID='transform' AIRFLOW_CTX_EXECUTION_DATE='2025-02-18T19:04:33.581267+00:00' AIRFLOW_CTX_TRY_NUMBER='1' AIRFLOW_CTX_DAG_RUN_ID='manual__2025-02-18T19:04:33.581267+00:00'
[2025-02-18T19:04:39.313+0000] {logging_mixin.py:149} INFO - üîç Ejecutando el comando: docker exec etl-pipeline-spark-1 /opt/spark/bin/spark-submit /scripts/spark_etl.py
[2025-02-18T19:04:39.651+0000] {logging_mixin.py:149} INFO - ‚ùå ERROR en Spark ETL:
[2025-02-18T19:04:39.653+0000] {taskinstance.py:1847} ERROR - Task failed with exception
Traceback (most recent call last):
  File "/home/airflow/.local/lib/python3.7/site-packages/airflow/operators/python.py", line 181, in execute
    return_value = self.execute_callable()
  File "/home/airflow/.local/lib/python3.7/site-packages/airflow/operators/python.py", line 198, in execute_callable
    return self.python_callable(*self.op_args, **self.op_kwargs)
  File "/opt/airflow/dags/etl_dag.py", line 22, in spark_etl
    shell=True  # Especificamos shell=True porque estamos ejecutando un comando de bash
  File "/usr/local/lib/python3.7/subprocess.py", line 512, in run
    output=stdout, stderr=stderr)
subprocess.CalledProcessError: Command 'docker exec etl-pipeline-spark-1 /opt/spark/bin/spark-submit /scripts/spark_etl.py' returned non-zero exit status 126.
[2025-02-18T19:04:39.678+0000] {taskinstance.py:1373} INFO - Marking task as UP_FOR_RETRY. dag_id=etl_pipeline, task_id=transform, execution_date=20250218T190433, start_date=20250218T190439, end_date=20250218T190439
[2025-02-18T19:04:39.702+0000] {standard_task_runner.py:109} ERROR - Failed to execute job 40 for task transform (Command 'docker exec etl-pipeline-spark-1 /opt/spark/bin/spark-submit /scripts/spark_etl.py' returned non-zero exit status 126.; 205)
[2025-02-18T19:04:39.749+0000] {local_task_job_runner.py:232} INFO - Task exited with return code 1
[2025-02-18T19:04:39.798+0000] {taskinstance.py:2674} INFO - 0 downstream tasks scheduled from follow-on schedule check
