[2025-02-18T15:06:13.154+0000] {taskinstance.py:1083} INFO - Dependencies all met for <TaskInstance: etl_pipeline.transform scheduled__2025-02-17T00:00:00+00:00 [queued]>
[2025-02-18T15:06:13.171+0000] {taskinstance.py:1083} INFO - Dependencies all met for <TaskInstance: etl_pipeline.transform scheduled__2025-02-17T00:00:00+00:00 [queued]>
[2025-02-18T15:06:13.172+0000] {taskinstance.py:1279} INFO - 
--------------------------------------------------------------------------------
[2025-02-18T15:06:13.173+0000] {taskinstance.py:1280} INFO - Starting attempt 2 of 2
[2025-02-18T15:06:13.174+0000] {taskinstance.py:1281} INFO - 
--------------------------------------------------------------------------------
[2025-02-18T15:06:13.198+0000] {taskinstance.py:1300} INFO - Executing <Task(PythonOperator): transform> on 2025-02-17 00:00:00+00:00
[2025-02-18T15:06:13.204+0000] {standard_task_runner.py:55} INFO - Started process 612 to run task
[2025-02-18T15:06:13.207+0000] {standard_task_runner.py:82} INFO - Running: ['***', 'tasks', 'run', 'etl_pipeline', 'transform', 'scheduled__2025-02-17T00:00:00+00:00', '--job-id', '20', '--raw', '--subdir', 'DAGS_FOLDER/etl_dag.py', '--cfg-path', '/tmp/tmp4qni0t_j']
[2025-02-18T15:06:13.210+0000] {standard_task_runner.py:83} INFO - Job 20: Subtask transform
[2025-02-18T15:06:13.227+0000] {logging_mixin.py:137} WARNING - /home/***/.local/lib/python3.7/site-packages/***/settings.py:249 DeprecationWarning: The sql_alchemy_conn option in [core] has been moved to the sql_alchemy_conn option in [database] - the old setting has been used, but please update your config.
[2025-02-18T15:06:13.260+0000] {logging_mixin.py:137} WARNING - /home/***/.local/lib/python3.7/site-packages/***/utils/sqlalchemy.py:124 DeprecationWarning: The sql_alchemy_conn option in [core] has been moved to the sql_alchemy_conn option in [database] - the old setting has been used, but please update your config.
[2025-02-18T15:06:13.300+0000] {task_command.py:388} INFO - Running <TaskInstance: etl_pipeline.transform scheduled__2025-02-17T00:00:00+00:00 [running]> on host bf9eef710f83
[2025-02-18T15:06:13.392+0000] {taskinstance.py:1509} INFO - Exporting the following env vars:
AIRFLOW_CTX_DAG_OWNER=***
AIRFLOW_CTX_DAG_ID=etl_pipeline
AIRFLOW_CTX_TASK_ID=transform
AIRFLOW_CTX_EXECUTION_DATE=2025-02-17T00:00:00+00:00
AIRFLOW_CTX_TRY_NUMBER=2
AIRFLOW_CTX_DAG_RUN_ID=scheduled__2025-02-17T00:00:00+00:00
[2025-02-18T15:06:13.394+0000] {logging_mixin.py:137} INFO - üîç Ejecutando el comando: docker exec spark-1 /opt/spark/bin/spark-submit /scripts/spark_etl.py
[2025-02-18T15:06:13.431+0000] {logging_mixin.py:137} INFO - ‚ùå ERROR en Spark ETL:
[2025-02-18T15:06:13.432+0000] {logging_mixin.py:137} INFO - Cannot connect to the Docker daemon at unix:///var/run/docker.sock. Is the docker daemon running?
[2025-02-18T15:06:13.433+0000] {taskinstance.py:1768} ERROR - Task failed with exception
Traceback (most recent call last):
  File "/home/airflow/.local/lib/python3.7/site-packages/airflow/operators/python.py", line 175, in execute
    return_value = self.execute_callable()
  File "/home/airflow/.local/lib/python3.7/site-packages/airflow/operators/python.py", line 192, in execute_callable
    return self.python_callable(*self.op_args, **self.op_kwargs)
  File "/opt/airflow/dags/etl_dag.py", line 23, in spark_etl
    shell=True  # Especificamos shell=True porque estamos ejecutando un comando de bash
  File "/usr/local/lib/python3.7/subprocess.py", line 512, in run
    output=stdout, stderr=stderr)
subprocess.CalledProcessError: Command 'docker exec spark-1 /opt/spark/bin/spark-submit /scripts/spark_etl.py' returned non-zero exit status 1.
[2025-02-18T15:06:13.446+0000] {taskinstance.py:1323} INFO - Marking task as FAILED. dag_id=etl_pipeline, task_id=transform, execution_date=20250217T000000, start_date=20250218T150613, end_date=20250218T150613
[2025-02-18T15:06:13.463+0000] {standard_task_runner.py:105} ERROR - Failed to execute job 20 for task transform (Command 'docker exec spark-1 /opt/spark/bin/spark-submit /scripts/spark_etl.py' returned non-zero exit status 1.; 612)
[2025-02-18T15:06:13.501+0000] {local_task_job.py:208} INFO - Task exited with return code 1
[2025-02-18T15:06:13.548+0000] {taskinstance.py:2578} INFO - 0 downstream tasks scheduled from follow-on schedule check
